Workbook

Sheet Dashboard
B2: SALES CASE STUDY — EXECUTIVE DASHBOARD
B3: Simulated daily trading data · single product · 30 Dec 2013 – 16 Nov 2016
B5: Total Sales | E5: Total Quantity Sold | H5: Overall Gross Profit % | K5: Avg Unit Price (weighted) | N5: Avg Daily GP %
B6: ='KPI Summary'!C8 -> 1.8690983e+08 | E6: ='KPI Summary'!C9 -> 1.9402611e+08 | H6: ='KPI Summary'!C11 -> -7116281.2 | K6: ='KPI Summary'!C14 -> 37.072852 | N6: ='KPI Summary'!C15 -> 35.400447
B43: Key Insights
B44: 1. Over the full 2013–2016 period the product is marginally loss-making overall (-3.8% gross profit), but the trend has turned: 2016 is the first year with a positive average gross profit margin (+2.6%), and 4 of the last 5 months in the dataset (Jul, Sep, Oct, Nov 2016) posted positive margins.
B46: 2. Demand for this product is highly price elastic. Across three tested promotional periods, PED ranged from -5.3 to -14.3 — a 10-15% price cut drove 50-170% more units sold per day.
B48: 3. That elasticity is a double-edged sword: every tested promo period had a negative gross profit % even though baseline (non-promo) margin was positive, meaning current promo discount depth is too aggressive relative to cost — volume gains do not offset the margin given away.
B50: 4. Weekends (especially Saturday) generate the highest average daily sales (~R279k) and volumes, but carry the thinnest margins of the week — weekend demand is more price-sensitive/promotion-driven.
B52: 5. Price and quantity are strongly negatively correlated (r ≈ -0.62) across the whole dataset, and price correlates positively with gross profit % (r ≈ +0.64) — confirming margin is protected at higher price points and volume is chased at lower ones.

Sheet Raw Data
A1: date | B1: sales | C1: cost_of_sales | D1: quantity_sold | E1: price_per_unit | F1: cost_per_unit | G1: gross_profit | H1: gross_profit_pct | I1: gross_profit_pct_per_unit | J1: year | K1: month | L1: week_of_year | M1: day_of_week | N1: is_weekend | O1: price_rolling_avg | P1: qty_rolling_avg | Q1: price_drop_pct | R1: qty_spike_pct | S1: promo_candidate
A2: 41638 | B2: 223937.97 | C2: 230079.62 | D2: 6827 | E2: 32.801812 | F2: 33.701424 | G2: -6141.6531 | H2: -0.027425689 | I2: -0.027425689 | J2: 2013 | K2: 12 | L2: 1 | M2: Monday | N2: =FALSE() -> FALSE | S2: =FALSE() -> FALSE
A3: 41639 | B3: 300345.48 | C3: 306986.12 | D3: 9268 | E3: 32.40672 | F3: 33.123233 | G3: -6640.6359 | H3: -0.022109991 | I3: -0.022109991 | J3: 2013 | K3: 12 | L3: 1 | M3: Tuesday | N3: =FALSE() -> FALSE | O3: 32.801812 | P3: 6827 | Q3: -0.012044799 | R3: 0.3575509 | S3: =FALSE() -> FALSE
A4: 41640 | B4: 86782.468 | C4: 87986.318 | D4: 2678 | E4: 32.405701 | F4: 32.855235 | G4: -1203.8505 | H4: -0.013872047 | I4: -0.013872047 | J4: 2014 | K4: 1 | L4: 1 | M4: Wednesday | N4: =FALSE() -> FALSE | O4: 32.604266 | P4: 8047.5 | Q4: -0.0060901488 | R4: -0.66722585 | S4: =FALSE() -> FALSE
A5: 41641 | B5: 200173.12 | C5: 202881.18 | D5: 6175 | E5: 32.416699 | F5: 32.855251 | G5: -2708.061 | H5: -0.013528595 | I5: -0.013528595 | J5: 2014 | K5: 1 | L5: 1 | M5: Thursday | N5: =FALSE() -> FALSE | O5: 32.538078 | P5: 6257.6667 | Q5: -0.0037303572 | R5: -0.013210462 | S5: =FALSE() -> FALSE
A6: 41642 | B6: 326906.07 | C6: 333806.29 | D6: 10084 | E6: 32.418294 | F6: 33.102568 | G6: -6900.2177 | H6: -0.021107646 | I6: -0.021107646 | J6: 2014 | K6: 1 | L6: 1 | M6: Friday | N6: =FALSE() -> FALSE | O6: 32.507733 | P6: 6237 | Q6: -0.0027513241 | R6: 0.61680295 | S6: =FALSE() -> FALSE
A7: 41643 | B7: 307043.94 | C7: 313652.35 | D7: 9470 | E7: 32.422802 | F7: 33.120628 | G7: -6608.4129 | H7: -0.021522695 | I7: -0.021522695 | J7: 2014 | K7: 1 | L7: 1 | M7: Saturday | N7: =TRUE() -> TRUE | O7: 32.489845 | P7: 7006.4 | Q7: -0.0020635108 | R7: 0.35162137 | S7: =FALSE() -> FALSE
A8: 41644 | B8: 179188.88 | C8: 183083.28 | D8: 5524 | E8: 32.438248 | F8: 33.143245 | G8: -3894.4005 | H8: -0.021733494 | I8: -0.021733494 | J8: 2014 | K8: 1 | L8: 1 | M8: Sunday | N8: =TRUE() -> TRUE | O8: 32.478671 | P8: 7417 | Q8: -0.0012445977 | R8: -0.25522448 | S8: =FALSE() -> FALSE
A9: 41645 | B9: 306351.95 | C9: 313446.07 | D9: 9448 | E9: 32.425058 | F9: 33.175917 | G9: -7094.1173 | H9: -0.023156756 | I9: -0.023156756 | J9: 2014 | K9: 1 | L9: 2 | M9: Monday | N9: =FALSE() -> FALSE | O9: 32.472897 | P9: 7146.5714 | Q9: -0.0014731774 | R9: 0.32203254 | S9: =FALSE() -> FALSE
A10: 41646 | B10: 224020.41 | C10: 229533.97 | D10: 6911 | E10: 32.41505 | F10: 33.212845 | G10: -5513.5638 | H10: -0.024611881 | I10: -0.024611881 | J10: 2014 | K10: 1 | L10: 2 | M10: Tuesday | N10: =FALSE() -> FALSE | O10: 32.466917 | P10: 7434.25 | Q10: -0.0015975319 | R10: -0.070383697 | S10: =FALSE() -> FALSE
A11: 41647 | B11: 101836.4 | C11: 99381.968 | D11: 2990 | E11: 34.058997 | F11: 33.238116 | G11: 2454.4347 | H11: 0.024101742 | I11: 0.024101742 | J11: 2014 | K11: 1 | L11: 2 | M11: Wednesday | N11: =FALSE() -> FALSE | O11: 32.461154 | P11: 7376.1111 | Q11: 0.049223252 | R11: -0.59463734 | S11: =FALSE() -> FALSE
A12: 41648 | B12: 107804.3 | C12: 104816.46 | D12: 3159 | E12: 34.126086 | F12: 33.180265 | G12: 2987.8464 | H12: 0.027715465 | I12: 0.027715465 | J12: 2014 | K12: 1 | L12: 2 | M12: Thursday | N12: =FALSE() -> FALSE | O12: 32.620938 | P12: 6937.5 | Q12: 0.046140536 | R12: -0.54464865 | S12: =FALSE() -> FALSE
A13: 41649 | B13: 144829.96 | C13: 141334 | D13: 4246 | E13: 34.10974 | F13: 33.286386 | G13: 3495.9604 | H13: 0.024138379 | I13: 0.024138379 | J13: 2014 | K13: 1 | L13: 2 | M13: Friday | N13: =FALSE() -> FALSE | O13: 32.75777 | P13: 6594 | Q13: 0.041271746 | R13: -0.35608129 | S13: =FALSE() -> FALSE
A14: 41650 | B14: 146571.48 | C14: 143179.67 | D14: 4297 | E14: 34.110189 | F14: 33.320845 | G14: 3391.8124 | H14: 0.023141012 | I14: 0.023141012 | J14: 2014 | K14: 1 | L14: 2 | M14: Saturday | N14: =TRUE() -> TRUE | O14: 32.870434 | P14: 6398.3333 | Q14: 0.037716419 | R14: -0.32841886 | S14: =FALSE() -> FALSE
A15: 41651 | B15: 95422.373 | C15: 93126.147 | D15: 2796 | E15: 34.128173 | F15: 33.30692 | G15: 2296.2257 | H15: 0.024063809 | I15: 0.024063809 | J15: 2014 | K15: 1 | L15: 2 | M15: Sunday | N15: =TRUE() -> TRUE | O15: 32.9658 | P15: 6236.6923 | Q15: 0.035259987 | R15: -0.55168543 | S15: =FALSE() -> FALSE
A16: 41652 | B16: 114883.17 | C16: 112186.31 | D16: 3369 | E16: 34.100081 | F16: 33.299587 | G16: 2696.8651 | H16: 0.023474849 | I16: 0.023474849 | J16: 2014 | K16: 1 | L16: 3 | M16: Monday | N16: =FALSE() -> FALSE | O16: 33.048826 | P16: 5990.9286 | Q16: 0.031809142 | R16: -0.43764978 | S16: =FALSE() -> FALSE
A17: 41653 | B17: 80090.8 | C17: 78096.76 | D17: 2348 | E17: 34.110221 | F17: 33.260971 | G17: 1994.0399 | H17: 0.02489724 | I17: 0.02489724 | J17: 2014 | K17: 1 | L17: 3 | M17: Tuesday | N17: =FALSE() -> FALSE | O17: 33.14156 | P17: 5743.9286 | Q17: 0.029227999 | R17: -0.59122054 | S17: =FALSE() -> FALSE
A18: 41654 | B18: 98945.371 | C18: 97159.003 | D18: 2903 | E18: 34.083834 | F18: 33.468482 | G18: 1786.3686 | H18: 0.018054089 | I18: 0.018054089 | J18: 2014 | K18: 1 | L18: 3 | M18: Wednesday | N18: =FALSE() -> FALSE | O18: 33.263239 | P18: 5249.6429 | Q18: 0.024669747 | R18: -0.44701 | S18: =FALSE() -> FALSE
A19: 41655 | B19: 84904.902 | C19: 83350.433 | D19: 2491 | E19: 34.084665 | F19: 33.460632 | G19: 1554.4686 | H19: 0.018308349 | I19: 0.018308349 | J19: 2014 | K19: 1 | L19: 3 | M19: Thursday | N19: =FALSE() -> FALSE | O19: 33.383105 | P19: 5265.7143 | Q19: 0.021015425 | R19: -0.52693977 | S19: =FALSE() -> FALSE
A20: 41656 | B20: 135460.62 | C20: 132703.34 | D20: 3968 | E20: 34.138261 | F20: 33.443381 | G20: 2757.2843 | H20: 0.020354877 | I20: 0.020354877 | J20: 2014 | K20: 1 | L20: 3 | M20: Friday | N20: =FALSE() -> FALSE | O20: 33.502246 | P20: 5002.5714 | Q20: 0.018984257 | R20: -0.20680793 | S20: =FALSE() -> FALSE
A21: 41657 | B21: 149925.75 | C21: 146928.41 | D21: 4393 | E21: 34.128329 | F21: 33.44603 | G21: 2997.3379 | H21: 0.019992149 | I21: 0.019992149 | J21: 2014 | K21: 1 | L21: 3 | M21: Saturday | N21: =TRUE() -> TRUE | O21: 33.625101 | P21: 4565.7143 | Q21: 0.014965859 | R21: -0.037828536 | S21: =FALSE() -> FALSE
A22: 41658 | B22: 74297.307 | C22: 72782.284 | D22: 2176 | E22: 34.143983 | F22: 33.447741 | G22: 1515.0229 | H22: 0.020391356 | I22: 0.020391356 | J22: 2014 | K22: 1 | L22: 3 | M22: Sunday | N22: =TRUE() -> TRUE | O22: 33.746924 | P22: 4203.0714 | Q22: 0.011765787 | R22: -0.48228336 | S22: =FALSE() -> FALSE
A23: 41659 | B23: 83356.425 | C23: 81789.136 | D23: 2443 | E23: 34.120518 | F23: 33.478975 | G23: 1567.2884 | H23: 0.018802251 | I23: 0.018802251 | J23: 2014 | K23: 1 | L23: 4 | M23: Monday | N23: =FALSE() -> FALSE | O23: 33.868762 | P23: 3963.9286 | Q23: 0.0074332653 | R23: -0.38369222 | S23: =FALSE() -> FALSE
A24: 41660 | B24: 89922.014 | C24: 88388.916 | D24: 2638 | E24: 34.087193 | F24: 33.506033 | G24: 1533.0982 | H24: 0.017049198 | I24: 0.017049198 | J24: 2014 | K24: 1 | L24: 4 | M24: Tuesday | N24: =FALSE() -> FALSE | O24: 33.989866 | P24: 3463.5714 | Q24: 0.0028633919 | R24: -0.23835842 | S24: =FALSE() -> FALSE
A25: 41661 | B25: 57806.303 | C25: 57157.283 | D25: 1704 | E25: 33.923887 | F25: 33.543006 | G25: 649.02024 | H25: 0.0112275 | I25: 0.0112275 | J25: 2014 | K25: 1 | L25: 4 | M25: Wednesday | N25: =FALSE() -> FALSE | O25: 34.109305 | P25: 3158.3571 | Q25: -0.0054360102 | R25: -0.460479 | S25: =FALSE() -> FALSE
A26: 41662 | B26: 63977.75 | C26: 62863.987 | D26: 1872 | E26: 34.176149 | F26: 33.58119 | G26: 1113.7631 | H26: 0.017408601 | I26: 0.017408601 | J26: 2014 | K26: 1 | L26: 4 | M26: Thursday | N26: =FALSE() -> FALSE | O26: 34.099654 | P26: 3066.5 | Q26: 0.002243258 | R26: -0.38953204 | S26: =FALSE() -> FALSE
A27: 41663 | B27: 116958.8 | C27: 114823.8 | D27: 3423 | E27: 34.168507 | F27: 33.544784 | G27: 2135.0046 | H27: 0.018254331 | I27: 0.018254331 | J27: 2014 | K27: 1 | L27: 4 | M27: Friday | N27: =FALSE() -> FALSE | O27: 34.10323 | P27: 2974.5714 | Q27: 0.001914095 | R27: 0.15075401 | S27: =FALSE() -> FALSE
A28: 41664 | B28: 155272.82 | C28: 152636.28 | D28: 4544 | E28: 34.170956 | F28: 33.59073 | G28: 2636.5482 | H28: 0.016980101 | I28: 0.016980101 | J28: 2014 | K28: 1 | L28: 4 | M28: Saturday | N28: =TRUE() -> TRUE | O28: 34.107428 | P28: 2915.7857 | Q28: 0.0018625923 | R28: 0.55841356 | S28: =FALSE() -> FALSE
A29: 41665 | B29: 82885.216 | C29: 81583.167 | D29: 2426 | E29: 34.165382 | F29: 33.628676 | G29: 1302.049 | H29: 0.015709062 | I29: 0.015709062 | J29: 2014 | K29: 1 | L29: 4 | M29: Sunday | N29: =TRUE() -> TRUE | O29: 34.111768 | P29: 2933.4286 | Q29: 0.0015716929 | R29: -0.1729814 | S29: =FALSE() -> FALSE
A30: 41666 | B30: 72353.426 | C30: 71377.156 | D30: 2117 | E30: 34.177339 | F30: 33.716182 | G30: 976.26943 | H30: 0.013493064 | I30: 0.013493064 | J30: 2014 | K30: 1 | L30: 5 | M30: Monday | N30: =FALSE() -> FALSE | O30: 34.114426 | P30: 2907 | Q30: 0.0018441601 | R30: -0.27175783 | S30: =FALSE() -> FALSE
A31: 41667 | B31: 50415.904 | C31: 49769.098 | D31: 1476 | E31: 34.157116 | F31: 33.718901 | G31: 646.80552 | H31: 0.012829395 | I31: 0.012829395 | J31: 2014 | K31: 1 | L31: 5 | M31: Tuesday | N31: =FALSE() -> FALSE | O31: 34.119945 | P31: 2817.5714 | Q31: 0.0010894455 | R31: -0.4761446 | S31: =FALSE() -> FALSE
A32: 41668 | B32: 67458.302 | C32: 66529.442 | D32: 1974 | E32: 34.173405 | F32: 33.702858 | G32: 928.85989 | H32: 0.013769393 | I32: 0.013769393 | J32: 2014 | K32: 1 | L32: 5 | M32: Wednesday | N32: =FALSE() -> FALSE | O32: 34.123294 | P32: 2755.2857 | Q32: 0.0014685285 | R32: -0.28355887 | S32: =FALSE() -> FALSE
A33: 41669 | B33: 64640.369 | C33: 63757.84 | D33: 1892 | E33: 34.1651 | F33: 33.698647 | G33: 882.52944 | H33: 0.013652915 | I33: 0.013652915 | J33: 2014 | K33: 1 | L33: 5 | M33: Thursday | N33: =FALSE() -> FALSE | O33: 34.129692 | P33: 2688.9286 | Q33: 0.0010374532 | R33: -0.29637402 | S33: =FALSE() -> FALSE
A34: 41670 | B34: 137693.87 | C34: 135609.51 | D34: 4030 | E34: 34.167214 | F34: 33.650002 | G34: 2084.3659 | H34: 0.015137681 | I34: 0.015137681 | J34: 2014 | K34: 1 | L34: 5 | M34: Friday | N34: =FALSE() -> FALSE | O34: 34.135437 | P34: 2646.1429 | Q34: 0.00093090471 | R34: 0.52297144 | S34: =FALSE() -> FALSE
A35: 41671 | B35: 181209.13 | C35: 178435.72 | D35: 5304 | E35: 34.164617 | F35: 33.641726 | G35: 2773.4131 | H35: 0.015305041 | I35: 0.015305041 | J35: 2014 | K35: 2 | L35: 5 | M35: Saturday | N35: =TRUE() -> TRUE | O35: 34.137506 | P35: 2650.5714 | Q35: 0.00079418414 | R35: 1.0010779 | S35: =FALSE() -> FALSE
A36: 41672 | B36: 113433.58 | C36: 111466.52 | D36: 3320 | E36: 34.166741 | F36: 33.574252 | G36: 1967.0642 | H36: 0.01734111 | I36: 0.01734111 | J36: 2014 | K36: 2 | L36: 5 | M36: Sunday | N36: =TRUE() -> TRUE | O36: 34.140098 | P36: 2715.6429 | Q36: 0.00078042449 | R36: 0.22254662 | S36: =FALSE() -> FALSE
A37: 41673 | B37: 143192.53 | C37: 140505.63 | D37: 4191 | E37: 34.166675 | F37: 33.525563 | G37: 2686.8986 | H37: 0.018764237 | I37: 0.018764237 | J37: 2014 | K37: 2 | L37: 6 | M37: Monday | N37: =FALSE() -> FALSE | O37: 34.141723 | P37: 2797.3571 | Q37: 0.00073082221 | R37: 0.49819983 | S37: =FALSE() -> FALSE
A38: 41674 | B38: 130126.65 | C38: 128496.29 | D38: 3809 | E38: 34.162943 | F38: 33.734914 | G38: 1630.3622 | H38: 0.012529041 | I38: 0.012529041 | J38: 2014 | K38: 2 | L38: 6 | M38: Tuesday | N38: =FALSE() -> FALSE | O38: 34.14502 | P38: 2922.2143 | Q38: 0.00052490749 | R38: 0.30346362 | S38: =FALSE() -> FALSE
A39: 41675 | B39: 187155.87 | C39: 195078.6 | D39: 5764 | E39: 32.46979 | F39: 33.84431 | G39: -7922.7348 | H39: -0.042332281 | I39: -0.042332281 | J39: 2014 | K39: 2 | L39: 6 | M39: Wednesday | N39: =FALSE() -> FALSE | O39: 34.150431 | P39: 3005.8571 | Q39: -0.049212877 | R39: 0.91758947 | S39: =FALSE() -> FALSE
A40: 41676 | B40: 102314.71 | C40: 101977.99 | D40: 3028 | E40: 33.789534 | F40: 33.678332 | G40: 336.71964 | H40: 0.0032910189 | I40: 0.0032910189 | J40: 2014 | K40: 2 | L40: 6 | M40: Thursday | N40: =FALSE() -> FALSE | O40: 34.046567 | P40: 3295.8571 | Q40: -0.0075494394 | R40: -0.08127086 | S40: =FALSE() -> FALSE
...

Sheet KPI Summary
B2: Sales Case Study — KPI Summary
B3: Metrics 1–4: daily price per unit, average unit price, daily % gross profit, daily % gross profit per unit
B5: Metric | C5: Value | D5: How it is calculated
B6: Date range | C6: =TEXT('Raw Data'!A2,"yyyy-mm-dd") & " to " & TEXT('Raw Data'!A1054,"yyyy-mm-dd") -> 2013-12-30 to 2016-11-16 | D6: Min / max of Raw Data date column
B7: Total days in dataset | C7: =COUNT('Raw Data'!A2:A1054) -> 1053 | D7: COUNT of daily records
B8: Total Sales (R) | C8: =SUM('Raw Data'!B2:B1054) -> 1.8690983e+08 | D8: SUM of daily Sales
B9: Total Cost of Sales (R) | C9: =SUM('Raw Data'!C2:C1054) -> 1.9402611e+08 | D9: SUM of daily Cost of Sales
B10: Total Quantity Sold (units) | C10: =SUM('Raw Data'!D2:D1054) -> 5279872 | D10: SUM of daily Quantity Sold
B11: Total Gross Profit (R) | C11: =SUM('Raw Data'!G2:G1054) -> -7116281.2 | D11: Total Sales − Total Cost of Sales
B12: Overall Gross Profit % | C12: =SUM('Raw Data'!G2:G1054)/SUM('Raw Data'!B2:B1054) -> -0.038073339 | D12: Total Gross Profit / Total Sales
B13: KPI 1 — Daily Sales Price per Unit | C13: =AVERAGE('Raw Data'!E2:E1054) -> 37.072852 | D13: Average of daily Sales÷Quantity (full series in 'Daily Metrics' sheet, Raw Data col E)
B14: KPI 2 — Average Unit Sales Price of Product (simple mean of daily price) | C14: =AVERAGE('Raw Data'!E2:E1054) -> 37.072852 | D14: AVERAGE of the daily price-per-unit column
B15: KPI 2b — Average Unit Sales Price (volume-weighted) | C15: =SUM('Raw Data'!B2:B1054)/SUM('Raw Data'!D2:D1054) -> 35.400447 | D15: Total Sales / Total Quantity Sold (weights by daily volume)
B16: KPI 3 — Average Daily % Gross Profit | C16: =AVERAGE('Raw Data'!H2:H1054) -> -0.0087497665 | D16: Average of daily (Sales−Cost)/Sales (full series in 'Daily Metrics' sheet)
B17: KPI 4 — Average Daily % Gross Profit per Unit | C17: =AVERAGE('Raw Data'!I2:I1054) -> -0.0087497665 | D17: Average of daily (Price/unit−Cost/unit)/Price per unit — mathematically identical to KPI 3
B19: Note: Gross Profit % and Gross Profit % per Unit are mathematically identical ((Sales−Cost)/Sales = (Price−Cost)/Price), confirmed to <1e-10 difference across all 1,053 days.

Sheet Daily Metrics
A1: Daily Metrics (1–4)
A2: Pulled directly from Raw Data via formulas — recalculates if Raw Data changes
A4: Date | B4: Daily Sales Price per Unit (R) | C4: Daily Cost per Unit (R) | D4: Daily % Gross Profit | E4: Daily % Gross Profit per Unit | F4: On Promotion?
A5: ='Raw Data'!A2 -> 41638 | B5: ='Raw Data'!E2 -> 32.801812 | C5: ='Raw Data'!F2 -> 33.701424 | D5: ='Raw Data'!H2 -> -0.027425689 | E5: ='Raw Data'!I2 -> -0.027425689 | F5: ='Raw Data'!S2 -> FALSE
A6: ='Raw Data'!A3 -> 41639 | B6: ='Raw Data'!E3 -> 32.40672 | C6: ='Raw Data'!F3 -> 33.123233 | D6: ='Raw Data'!H3 -> -0.022109991 | E6: ='Raw Data'!I3 -> -0.022109991 | F6: ='Raw Data'!S3 -> FALSE
A7: ='Raw Data'!A4 -> 41640 | B7: ='Raw Data'!E4 -> 32.405701 | C7: ='Raw Data'!F4 -> 32.855235 | D7: ='Raw Data'!H4 -> -0.013872047 | E7: ='Raw Data'!I4 -> -0.013872047 | F7: ='Raw Data'!S4 -> FALSE
A8: ='Raw Data'!A5 -> 41641 | B8: ='Raw Data'!E5 -> 32.416699 | C8: ='Raw Data'!F5 -> 32.855251 | D8: ='Raw Data'!H5 -> -0.013528595 | E8: ='Raw Data'!I5 -> -0.013528595 | F8: ='Raw Data'!S5 -> FALSE
A9: ='Raw Data'!A6 -> 41642 | B9: ='Raw Data'!E6 -> 32.418294 | C9: ='Raw Data'!F6 -> 33.102568 | D9: ='Raw Data'!H6 -> -0.021107646 | E9: ='Raw Data'!I6 -> -0.021107646 | F9: ='Raw Data'!S6 -> FALSE
A10: ='Raw Data'!A7 -> 41643 | B10: ='Raw Data'!E7 -> 32.422802 | C10: ='Raw Data'!F7 -> 33.120628 | D10: ='Raw Data'!H7 -> -0.021522695 | E10: ='Raw Data'!I7 -> -0.021522695 | F10: ='Raw Data'!S7 -> FALSE
A11: ='Raw Data'!A8 -> 41644 | B11: ='Raw Data'!E8 -> 32.438248 | C11: ='Raw Data'!F8 -> 33.143245 | D11: ='Raw Data'!H8 -> -0.021733494 | E11: ='Raw Data'!I8 -> -0.021733494 | F11: ='Raw Data'!S8 -> FALSE
A12: ='Raw Data'!A9 -> 41645 | B12: ='Raw Data'!E9 -> 32.425058 | C12: ='Raw Data'!F9 -> 33.175917 | D12: ='Raw Data'!H9 -> -0.023156756 | E12: ='Raw Data'!I9 -> -0.023156756 | F12: ='Raw Data'!S9 -> FALSE
A13: ='Raw Data'!A10 -> 41646 | B13: ='Raw Data'!E10 -> 32.41505 | C13: ='Raw Data'!F10 -> 33.212845 | D13: ='Raw Data'!H10 -> -0.024611881 | E13: ='Raw Data'!I10 -> -0.024611881 | F13: ='Raw Data'!S10 -> FALSE
A14: ='Raw Data'!A11 -> 41647 | B14: ='Raw Data'!E11 -> 34.058997 | C14: ='Raw Data'!F11 -> 33.238116 | D14: ='Raw Data'!H11 -> 0.024101742 | E14: ='Raw Data'!I11 -> 0.024101742 | F14: ='Raw Data'!S11 -> FALSE
A15: ='Raw Data'!A12 -> 41648 | B15: ='Raw Data'!E12 -> 34.126086 | C15: ='Raw Data'!F12 -> 33.180265 | D15: ='Raw Data'!H12 -> 0.027715465 | E15: ='Raw Data'!I12 -> 0.027715465 | F15: ='Raw Data'!S12 -> FALSE
A16: ='Raw Data'!A13 -> 41649 | B16: ='Raw Data'!E13 -> 34.10974 | C16: ='Raw Data'!F13 -> 33.286386 | D16: ='Raw Data'!H13 -> 0.024138379 | E16: ='Raw Data'!I13 -> 0.024138379 | F16: ='Raw Data'!S13 -> FALSE
... A1057: ='Raw Data'!A1054 -> 42690 | B1057: ='Raw Data'!E1054 -> 43.805997 | C1057: ='Raw Data'!F1054 -> 40.515525 | D1057: ='Raw Data'!H1054 -> 0.075114645 | E1057: ='Raw Data'!I1054 -> 0.075114645 | F1057: ='Raw Data'!S1054 -> FALSE

Sheet Pivot - Monthly
A1: Monthly Sales Pivot
A2: Built with SUMIFS / AVERAGEIFS against Raw Data (year, month columns)
A4: Year-Month | B4: Total Sales (R) | C4: Total Quantity | D4: Total Gross Profit (R) | E4: Gross Profit % | F4: Avg Price per Unit (R)
A5: 2013-12 | B5: =SUMIFS('Raw Data'!$B$2:$B$1054,'Raw Data'!$J$2:$J$1054,2013,'Raw Data'!$K$2:$K$1054,12) -> 524283.45 | C5: =SUMIFS('Raw Data'!$D$2:$D$1054,'Raw Data'!$J$2:$J$1054,2013,'Raw Data'!$K$2:$K$1054,12) -> 16095 | D5: =SUMIFS('Raw Data'!$G$2:$G$1054,'Raw Data'!$J$2:$J$1054,2013,'Raw Data'!$K$2:$K$1054,12) -> -12782.289 | E5: =D5/B5 -> -0.024380493 | F5: =AVERAGEIFS('Raw Data'!$E$2:$E$1054,'Raw Data'!$J$2:$J$1054,2013,'Raw Data'!$K$2:$K$1054,12) -> 32.604266
A6: 2014-01 | B6: =SUMIFS('Raw Data'!$B$2:$B$1054,'Raw Data'!$J$2:$J$1054,2014,'Raw Data'!$K$2:$K$1054,1) -> 4008180.5 | C6: =SUMIFS('Raw Data'!$D$2:$D$1054,'Raw Data'!$J$2:$J$1054,2014,'Raw Data'!$K$2:$K$1054,1) -> 119965 | D6: =SUMIFS('Raw Data'!$G$2:$G$1054,'Raw Data'!$J$2:$J$1054,2014,'Raw Data'!$K$2:$K$1054,1) -> 12460.645 | E6: =D6/B6 -> 0.0031088035 | F6: =AVERAGEIFS('Raw Data'!$E$2:$E$1054,'Raw Data'!$J$2:$J$1054,2014,'Raw Data'!$K$2:$K$1054,1) -> 33.739264
A7: 2014-02 | B7: =SUMIFS('Raw Data'!$B$2:$B$1054,'Raw Data'!$J$2:$J$1054,2014,'Raw Data'!$K$2:$K$1054,2) -> 5780487.2 | C7: =SUMIFS('Raw Data'!$D$2:$D$1054,'Raw Data'!$J$2:$J$1054,2014,'Raw Data'!$K$2:$K$1054,2) -> 178035 | D7: =SUMIFS('Raw Data'!$G$2:$G$1054,'Raw Data'!$J$2:$J$1054,2014,'Raw Data'!$K$2:$K$1054,2) -> -132991.39 | E7: =D7/B7 -> -0.023006951 | F7: =AVERAGEIFS('Raw Data'!$E$2:$E$1054,'Raw Data'!$J$2:$J$1054,2014,'Raw Data'!$K$2:$K$1054,2) -> 32.766452
A8: 2014-03 | B8: =SUMIFS('Raw Data'!$B$2:$B$1054,'Raw Data'!$J$2:$J$1054,2014,'Raw Data'!$K$2:$K$1054,3) -> 8279517.2 | C8: =SUMIFS('Raw Data'!$D$2:$D$1054,'Raw Data'!$J$2:$J$1054,2014,'Raw Data'!$K$2:$K$1054,3) -> 252836 | D8: =SUMIFS('Raw Data'!$G$2:$G$1054,'Raw Data'!$J$2:$J$1054,2014,'Raw Data'!$K$2:$K$1054,3) -> -136136.84 | E8: =D8/B8 -> -0.016442607 | F8: =AVERAGEIFS('Raw Data'!$E$2:$E$1054,'Raw Data'!$J$2:$J$1054,2014,'Raw Data'!$K$2:$K$1054,3) -> 33.280478
A9: 2014-04 | B9: =SUMIFS('Raw Data'!$B$2:$B$1054,'Raw Data'!$J$2:$J$1054,2014,'Raw Data'!$K$2:$K$1054,4) -> 6435743.3 | C9: =SUMIFS('Raw Data'!$D$2:$D$1054,'Raw Data'!$J$2:$J$1054,2014,'Raw Data'!$K$2:$K$1054,4) -> 190091 | D9: =SUMIFS('Raw Data'!$G$2:$G$1054,'Raw Data'!$J$2:$J$1054,2014,'Raw Data'!$K$2:$K$1054,4) -> -43900.351 | E9: =D9/B9 -> -0.0068213335 | F9: =AVERAGEIFS('Raw Data'!$E$2:$E$1054,'Raw Data'!$J$2:$J$1054,2014,'Raw Data'!$K$2:$K$1054,4) -> 34.062178
A10: 2014-05 | B10: =SUMIFS('Raw Data'!$B$2:$B$1054,'Raw Data'!$J$2:$J$1054,2014,'Raw Data'!$K$2:$K$1054,5) -> 7694906.2 | C10: =SUMIFS('Raw Data'!$D$2:$D$1054,'Raw Data'!$J$2:$J$1054,2014,'Raw Data'!$K$2:$K$1054,5) -> 235793 | D10: =SUMIFS('Raw Data'!$G$2:$G$1054,'Raw Data'!$J$2:$J$1054,2014,'Raw Data'!$K$2:$K$1054,5) -> -322334.26 | E10: =D10/B10 -> -0.041889304 | F10: =AVERAGEIFS('Raw Data'!$E$2:$E$1054,'Raw Data'!$J$2:$J$1054,2014,'Raw Data'!$K$2:$K$1054,5) -> 33.114192
A11: 2014-06 | B11: =SUMIFS('Raw Data'!$B$2:$B$1054,'Raw Data'!$J$2:$J$1054,2014,'Raw Data'!$K$2:$K$1054,6) -> 6456943.6 | C11: =SUMIFS('Raw Data'!$D$2:$D$1054,'Raw Data'!$J$2:$J$1054,2014,'Raw Data'!$K$2:$K$1054,6) -> 198857 | D11: =SUMIFS('Raw Data'!$G$2:$G$1054,'Raw Data'!$J$2:$J$1054,2014,'Raw Data'!$K$2:$K$1054,6) -> -188900.01 | E11: =D11/B11 -> -0.029255329 | F11: =AVERAGEIFS('Raw Data'!$E$2:$E$1054,'Raw Data'!$J$2:$J$1054,2014,'Raw Data'!$K$2:$K$1054,6) -> 32.943879
A12: 2014-07 | B12: =SUMIFS('Raw Data'!$B$2:$B$1054,'Raw Data'!$J$2:$J$1054,2014,'Raw Data'!$K$2:$K$1054,7) -> 4933710.8 | C12: =SUMIFS('Raw Data'!$D$2:$D$1054,'Raw Data'!$J$2:$J$1054,2014,'Raw Data'!$K$2:$K$1054,7) -> 147449 | D12: =SUMIFS('Raw Data'!$G$2:$G$1054,'Raw Data'!$J$2:$J$1054,2014,'Raw Data'!$K$2:$K$1054,7) -> -71184.101 | E12: =D12/B12 -> -0.014428106 | F12: =AVERAGEIFS('Raw Data'!$E$2:$E$1054,'Raw Data'!$J$2:$J$1054,2014,'Raw Data'!$K$2:$K$1054,7) -> 34.201254
A13: 2014-08 | B13: =SUMIFS('Raw Data'!$B$2:$B$1054,'Raw Data'!$J$2:$J$1054,2014,'Raw Data'!$K$2:$K$1054,8) -> 10010378 | C13: =SUMIFS('Raw Data'!$D$2:$D$1054,'Raw Data'!$J$2:$J$1054,2014,'Raw Data'!$K$2:$K$1054,8) -> 310572 | D13: =SUMIFS('Raw Data'!$G$2:$G$1054,'Raw Data'!$J$2:$J$1054,2014,'Raw Data'!$K$2:$K$1054,8) -> -514054.14 | E13: =D13/B13 -> -0.051352119 | F13: =AVERAGEIFS('Raw Data'!$E$2:$E$1054,'Raw Data'!$J$2:$J$1054,2014,'Raw Data'!$K$2:$K$1054,8) -> 32.495681
A14: 2014-09 | B14: =SUMIFS('Raw Data'!$B$2:$B$1054,'Raw Data'!$J$2:$J$1054,2014,'Raw Data'!$K$2:$K$1054,9) -> 7643452.7 | C14: =SUMIFS('Raw Data'!$D$2:$D$1054,'Raw Data'!$J$2:$J$1054,2014,'Raw Data'!$K$2:$K$1054,9) -> 237742 | D14: =SUMIFS('Raw Data'!$G$2:$G$1054,'Raw Data'!$J$2:$J$1054,2014,'Raw Data'!$K$2:$K$1054,9) -> -550107.35 | E14: =D14/B14 -> -0.071971055 | F14: =AVERAGEIFS('Raw Data'!$E$2:$E$1054,'Raw Data'!$J$2:$J$1054,2014,'Raw Data'!$K$2:$K$1054,9) -> 33.285362
A15: 2014-10 | B15: =SUMIFS('Raw Data'!$B$2:$B$1054,'Raw Data'!$J$2:$J$1054,2014,'Raw Data'!$K$2:$K$1054,10) -> 5924683.4 | C15: =SUMIFS('Raw Data'!$D$2:$D$1054,'Raw Data'!$J$2:$J$1054,2014,'Raw Data'!$K$2:$K$1054,10) -> 171709 | D15: =SUMIFS('Raw Data'!$G$2:$G$1054,'Raw Data'!$J$2:$J$1054,2014,'Raw Data'!$K$2:$K$1054,10) -> -113777.94 | E15: =D15/B15 -> -0.019204053 | F15: =AVERAGEIFS('Raw Data'!$E$2:$E$1054,'Raw Data'!$J$2:$J$1054,2014,'Raw Data'!$K$2:$K$1054,10) -> 35.905736
A16: 2014-11 | B16: =SUMIFS('Raw Data'!$B$2:$B$1054,'Raw Data'!$J$2:$J$1054,2014,'Raw Data'!$K$2:$K$1054,11) -> 2631353.3 | C16: =SUMIFS('Raw Data'!$D$2:$D$1054,'Raw Data'!$J$2:$J$1054,2014,'Raw Data'!$K$2:$K$1054,11) -> 68569 | D16: =SUMIFS('Raw Data'!$G$2:$G$1054,'Raw Data'!$J$2:$J$1054,2014,'Raw Data'!$K$2:$K$1054,11) -> 114228.51 | E16: =D16/B16 -> 0.043410554 | F16: =AVERAGEIFS('Raw Data'!$E$2:$E$1054,'Raw Data'!$J$2:$J$1054,2014,'Raw Data'!$K$2:$K$1054,11) -> 39.257755
A17: 2014-12 | B17: =SUMIFS('Raw Data'!$B$2:$B$1054,'Raw Data'!$J$2:$J$1054,2014,'Raw Data'!$K$2:$K$1054,12) -> 5615619.3 | C17: =SUMIFS('Raw Data'!$D$2:$D$1054,'Raw Data'!$J$2:$J$1054,2014,'Raw Data'!$K$2:$K$1054,12) -> 142612 | D17: =SUMIFS('Raw Data'!$G$2:$G$1054,'Raw Data'!$J$2:$J$1054,2014,'Raw Data'!$K$2:$K$1054,12) -> -319176.76 | E17: =D17/B17 -> -0.056837322 | F17: =AVERAGEIFS('Raw Data'!$E$2:$E$1054,'Raw Data'!$J$2:$J$1054,2014,'Raw Data'!$K$2:$K$1054,12) -> 39.695771
A18: 2015-01 | B18: =SUMIFS('Raw Data'!$B$2:$B$1054,'Raw Data'!$J$2:$J$1054,2015,'Raw Data'!$K$2:$K$1054,1) -> 3696191.5 | C18: =SUMIFS('Raw Data'!$D$2:$D$1054,'Raw Data'!$J$2:$J$1054,2015,'Raw Data'!$K$2:$K$1054,1) -> 91740 | D18: =SUMIFS('Raw Data'!$G$2:$G$1054,'Raw Data'!$J$2:$J$1054,2015,'Raw Data'!$K$2:$K$1054,1) -> -155068.96 | E18: =D18/B18 -> -0.041953713 | F18: =AVERAGEIFS('Raw Data'!$E$2:$E$1054,'Raw Data'!$J$2:$J$1054,2015,'Raw Data'!$K$2:$K$1054,1) -> 40.673899
A19: 2015-02 | B19: =SUMIFS('Raw Data'!$B$2:$B$1054,'Raw Data'!$J$2:$J$1054,2015,'Raw Data'!$K$2:$K$1054,2) -> 4901504.9 | C19: =SUMIFS('Raw Data'!$D$2:$D$1054,'Raw Data'!$J$2:$J$1054,2015,'Raw Data'!$K$2:$K$1054,2) -> 127753 | D19: =SUMIFS('Raw Data'!$G$2:$G$1054,'Raw Data'!$J$2:$J$1054,2015,'Raw Data'!$K$2:$K$1054,2) -> -250251.37 | E19: =D19/B19 -> -0.051056029 | F19: =AVERAGEIFS('Raw Data'!$E$2:$E$1054,'Raw Data'!$J$2:$J$1054,2015,'Raw Data'!$K$2:$K$1054,2) -> 38.922637
A20: 2015-03 | B20: =SUMIFS('Raw Data'!$B$2:$B$1054,'Raw Data'!$J$2:$J$1054,2015,'Raw Data'!$K$2:$K$1054,3) -> 5269353.2 | C20: =SUMIFS('Raw Data'!$D$2:$D$1054,'Raw Data'!$J$2:$J$1054,2015,'Raw Data'!$K$2:$K$1054,3) -> 136673 | D20: =SUMIFS('Raw Data'!$G$2:$G$1054,'Raw Data'!$J$2:$J$1054,2015,'Raw Data'!$K$2:$K$1054,3) -> -330277.57 | E20: =D20/B20 -> -0.062678958 | F20: =AVERAGEIFS('Raw Data'!$E$2:$E$1054,'Raw Data'!$J$2:$J$1054,2015,'Raw Data'!$K$2:$K$1054,3) -> 39.514039
A21: 2015-04 | B21: =SUMIFS('Raw Data'!$B$2:$B$1054,'Raw Data'!$J$2:$J$1054,2015,'Raw Data'!$K$2:$K$1054,4) -> 5963994 | C21: =SUMIFS('Raw Data'!$D$2:$D$1054,'Raw Data'!$J$2:$J$1054,2015,'Raw Data'!$K$2:$K$1054,4) -> 153702 | D21: =SUMIFS('Raw Data'!$G$2:$G$1054,'Raw Data'!$J$2:$J$1054,2015,'Raw Data'!$K$2:$K$1054,4) -> -322679.7 | E21: =D21/B21 -> -0.054104632 | F21: =AVERAGEIFS('Raw Data'!$E$2:$E$1054,'Raw Data'!$J$2:$J$1054,2015,'Raw Data'!$K$2:$K$1054,4) -> 39.977304
A22: 2015-05 | B22: =SUMIFS('Raw Data'!$B$2:$B$1054,'Raw Data'!$J$2:$J$1054,2015,'Raw Data'!$K$2:$K$1054,5) -> 8384367.2 | C22: =SUMIFS('Raw Data'!$D$2:$D$1054,'Raw Data'!$J$2:$J$1054,2015,'Raw Data'!$K$2:$K$1054,5) -> 220775 | D22: =SUMIFS('Raw Data'!$G$2:$G$1054,'Raw Data'!$J$2:$J$1054,2015,'Raw Data'!$K$2:$K$1054,5) -> -589334.66 | E22: =D22/B22 -> -0.0702897 | F22: =AVERAGEIFS('Raw Data'!$E$2:$E$1054,'Raw Data'!$J$2:$J$1054,2015,'Raw Data'!$K$2:$K$1054,5) -> 38.12341
A23: 2015-06 | B23: =SUMIFS('Raw Data'!$B$2:$B$1054,'Raw Data'!$J$2:$J$1054,2015,'Raw Data'!$K$2:$K$1054,6) -> 5332108.3 | C23: =SUMIFS('Raw Data'!$D$2:$D$1054,'Raw Data'!$J$2:$J$1054,2015,'Raw Data'!$K$2:$K$1054,6) -> 136581 | D23: =SUMIFS('Raw Data'!$G$2:$G$1054,'Raw Data'!$J$2:$J$1054,2015,'Raw Data'!$K$2:$K$1054,6) -> -188817.05 | E23: =D23/B23 -> -0.03541133 | F23: =AVERAGEIFS('Raw Data'!$E$2:$E$1054,'Raw Data'!$J$2:$J$1054,2015,'Raw Data'!$K$2:$K$1054,6) -> 40.037434
A24: 2015-07 | B24: =SUMIFS('Raw Data'!$B$2:$B$1054,'Raw Data'!$J$2:$J$1054,2015,'Raw Data'!$K$2:$K$1054,7) -> 3677692.4 | C24: =SUMIFS('Raw Data'!$D$2:$D$1054,'Raw Data'!$J$2:$J$1054,2015,'Raw Data'!$K$2:$K$1054,7) -> 95600 | D24: =SUMIFS('Raw Data'!$G$2:$G$1054,'Raw Data'!$J$2:$J$1054,2015,'Raw Data'!$K$2:$K$1054,7) -> -151496.17 | E24: =D24/B24 -> -0.041193269 | F24: =AVERAGEIFS('Raw Data'!$E$2:$E$1054,'Raw Data'!$J$2:$J$1054,2015,'Raw Data'!$K$2:$K$1054,7) -> 38.735437
A25: 2015-08 | B25: =SUMIFS('Raw Data'!$B$2:$B$1054,'Raw Data'!$J$2:$J$1054,2015,'Raw Data'!$K$2:$K$1054,8) -> 3934668.4 | C25: =SUMIFS('Raw Data'!$D$2:$D$1054,'Raw Data'!$J$2:$J$1054,2015,'Raw Data'!$K$2:$K$1054,8) -> 108899 | D25: =SUMIFS('Raw Data'!$G$2:$G$1054,'Raw Data'!$J$2:$J$1054,2015,'Raw Data'!$K$2:$K$1054,8) -> -276258.93 | E25: =D25/B25 -> -0.070211489 | F25: =AVERAGEIFS('Raw Data'!$E$2:$E$1054,'Raw Data'!$J$2:$J$1054,2015,'Raw Data'!$K$2:$K$1054,8) -> 37.575361
A26: 2015-09 | B26: =SUMIFS('Raw Data'!$B$2:$B$1054,'Raw Data'!$J$2:$J$1054,2015,'Raw Data'!$K$2:$K$1054,9) -> 4669899.9 | C26: =SUMIFS('Raw Data'!$D$2:$D$1054,'Raw Data'!$J$2:$J$1054,2015,'Raw Data'!$K$2:$K$1054,9) -> 134837 | D26: =SUMIFS('Raw Data'!$G$2:$G$1054,'Raw Data'!$J$2:$J$1054,2015,'Raw Data'!$K$2:$K$1054,9) -> -354594.84 | E26: =D26/B26 -> -0.075932 | F26: =AVERAGEIFS('Raw Data'!$E$2:$E$1054,'Raw Data'!$J$2:$J$1054,2015,'Raw Data'!$K$2:$K$1054,9) -> 36.454853
A27: 2015-10 | B27: =SUMIFS('Raw Data'!$B$2:$B$1054,'Raw Data'!$J$2:$J$1054,2015,'Raw Data'!$K$2:$K$1054,10) -> 4828975.1 | C27: =SUMIFS('Raw Data'!$D$2:$D$1054,'Raw Data'!$J$2:$J$1054,2015,'Raw Data'!$K$2:$K$1054,10) -> 135328 | D27: =SUMIFS('Raw Data'!$G$2:$G$1054,'Raw Data'!$J$2:$J$1054,2015,'Raw Data'!$K$2:$K$1054,10) -> -346519 | E27: =D27/B27 -> -0.071758291 | F27: =AVERAGEIFS('Raw Data'!$E$2:$E$1054,'Raw Data'!$J$2:$J$1054,2015,'Raw Data'!$K$2:$K$1054,10) -> 37.399806
A28: 2015-11 | B28: =SUMIFS('Raw Data'!$B$2:$B$1054,'Raw Data'!$J$2:$J$1054,2015,'Raw Data'!$K$2:$K$1054,11) -> 6538148.9 | C28: =SUMIFS('Raw Data'!$D$2:$D$1054,'Raw Data'!$J$2:$J$1054,2015,'Raw Data'!$K$2:$K$1054,11) -> 185868 | D28: =SUMIFS('Raw Data'!$G$2:$G$1054,'Raw Data'!$J$2:$J$1054,2015,'Raw Data'!$K$2:$K$1054,11) -> -600684.57 | E28: =D28/B28 -> -0.091873798 | F28: =AVERAGEIFS('Raw Data'!$E$2:$E$1054,'Raw Data'!$J$2:$J$1054,2015,'Raw Data'!$K$2:$K$1054,11) -> 35.609829
A29: 2015-12 | B29: =SUMIFS('Raw Data'!$B$2:$B$1054,'Raw Data'!$J$2:$J$1054,2015,'Raw Data'!$K$2:$K$1054,12) -> 6820689.7 | C29: =SUMIFS('Raw Data'!$D$2:$D$1054,'Raw Data'!$J$2:$J$1054,2015,'Raw Data'!$K$2:$K$1054,12) -> 187333 | D29: =SUMIFS('Raw Data'!$G$2:$G$1054,'Raw Data'!$J$2:$J$1054,2015,'Raw Data'!$K$2:$K$1054,12) -> -333627.64 | E29: =D29/B29 -> -0.048914063 | F29: =AVERAGEIFS('Raw Data'!$E$2:$E$1054,'Raw Data'!$J$2:$J$1054,2015,'Raw Data'!$K$2:$K$1054,12) -> 36.923677
A30: 2016-01 | B30: =SUMIFS('Raw Data'!$B$2:$B$1054,'Raw Data'!$J$2:$J$1054,2016,'Raw Data'!$K$2:$K$1054,1) -> 5403090.5 | C30: =SUMIFS('Raw Data'!$D$2:$D$1054,'Raw Data'!$J$2:$J$1054,2016,'Raw Data'!$K$2:$K$1054,1) -> 150561 | D30: =SUMIFS('Raw Data'!$G$2:$G$1054,'Raw Data'!$J$2:$J$1054,2016,'Raw Data'!$K$2:$K$1054,1) -> -254252.21 | E30: =D30/B30 -> -0.04705681 | F30: =AVERAGEIFS('Raw Data'!$E$2:$E$1054,'Raw Data'!$J$2:$J$1054,2016,'Raw Data'!$K$2:$K$1054,1) -> 37.60274
A31: 2016-02 | B31: =SUMIFS('Raw Data'!$B$2:$B$1054,'Raw Data'!$J$2:$J$1054,2016,'Raw Data'!$K$2:$K$1054,2) -> 4891882.3 | C31: =SUMIFS('Raw Data'!$D$2:$D$1054,'Raw Data'!$J$2:$J$1054,2016,'Raw Data'!$K$2:$K$1054,2) -> 132990 | D31: =SUMIFS('Raw Data'!$G$2:$G$1054,'Raw Data'!$J$2:$J$1054,2016,'Raw Data'!$K$2:$K$1054,2) -> 2578.6644 | E31: =D31/B31 -> 0.00052713133 | F31: =AVERAGEIFS('Raw Data'!$E$2:$E$1054,'Raw Data'!$J$2:$J$1054,2016,'Raw Data'!$K$2:$K$1054,2) -> 38.49059
A32: 2016-03 | B32: =SUMIFS('Raw Data'!$B$2:$B$1054,'Raw Data'!$J$2:$J$1054,2016,'Raw Data'!$K$2:$K$1054,3) -> 2951856 | C32: =SUMIFS('Raw Data'!$D$2:$D$1054,'Raw Data'!$J$2:$J$1054,2016,'Raw Data'!$K$2:$K$1054,3) -> 74185 | D32: =SUMIFS('Raw Data'!$G$2:$G$1054,'Raw Data'!$J$2:$J$1054,2016,'Raw Data'!$K$2:$K$1054,3) -> 34054.514 | E32: =D32/B32 -> 0.011536645 | F32: =AVERAGEIFS('Raw Data'!$E$2:$E$1054,'Raw Data'!$J$2:$J$1054,2016,'Raw Data'!$K$2:$K$1054,3) -> 40.3441
A33: 2016-04 | B33: =SUMIFS('Raw Data'!$B$2:$B$1054,'Raw Data'!$J$2:$J$1054,2016,'Raw Data'!$K$2:$K$1054,4) -> 6656880.2 | C33: =SUMIFS('Raw Data'!$D$2:$D$1054,'Raw Data'!$J$2:$J$1054,2016,'Raw Data'!$K$2:$K$1054,4) -> 190235 | D33: =SUMIFS('Raw Data'!$G$2:$G$1054,'Raw Data'!$J$2:$J$1054,2016,'Raw Data'!$K$2:$K$1054,4) -> -470851.73 | E33: =D33/B33 -> -0.070731591 | F33: =AVERAGEIFS('Raw Data'!$E$2:$E$1054,'Raw Data'!$J$2:$J$1054,2016,'Raw Data'!$K$2:$K$1054,4) -> 35.564621
A34: 2016-05 | B34: =SUMIFS('Raw Data'!$B$2:$B$1054,'Raw Data'!$J$2:$J$1054,2016,'Raw Data'!$K$2:$K$1054,5) -> 5170231.9 | C34: =SUMIFS('Raw Data'!$D$2:$D$1054,'Raw Data'!$J$2:$J$1054,2016,'Raw Data'!$K$2:$K$1054,5) -> 146298 | D34: =SUMIFS('Raw Data'!$G$2:$G$1054,'Raw Data'!$J$2:$J$1054,2016,'Raw Data'!$K$2:$K$1054,5) -> -168162.78 | E34: =D34/B34 -> -0.032525191 | F34: =AVERAGEIFS('Raw Data'!$E$2:$E$1054,'Raw Data'!$J$2:$J$1054,2016,'Raw Data'!$K$2:$K$1054,5) -> 38.039882
A35: 2016-06 | B35: =SUMIFS('Raw Data'!$B$2:$B$1054,'Raw Data'!$J$2:$J$1054,2016,'Raw Data'!$K$2:$K$1054,6) -> 6771134.9 | C35: =SUMIFS('Raw Data'!$D$2:$D$1054,'Raw Data'!$J$2:$J$1054,2016,'Raw Data'!$K$2:$K$1054,6) -> 197469 | D35: =SUMIFS('Raw Data'!$G$2:$G$1054,'Raw Data'!$J$2:$J$1054,2016,'Raw Data'!$K$2:$K$1054,6) -> -397214.69 | E35: =D35/B35 -> -0.058662942 | F35: =AVERAGEIFS('Raw Data'!$E$2:$E$1054,'Raw Data'!$J$2:$J$1054,2016,'Raw Data'!$K$2:$K$1054,6) -> 34.827885
A36: 2016-07 | B36: =SUMIFS('Raw Data'!$B$2:$B$1054,'Raw Data'!$J$2:$J$1054,2016,'Raw Data'!$K$2:$K$1054,7) -> 3324825.4 | C36: =SUMIFS('Raw Data'!$D$2:$D$1054,'Raw Data'!$J$2:$J$1054,2016,'Raw Data'!$K$2:$K$1054,7) -> 90653 | D36: =SUMIFS('Raw Data'!$G$2:$G$1054,'Raw Data'!$J$2:$J$1054,2016,'Raw Data'!$K$2:$K$1054,7) -> 56428.159 | E36: =D36/B36 -> 0.016971766 | F36: =AVERAGEIFS('Raw Data'!$E$2:$E$1054,'Raw Data'!$J$2:$J$1054,2016,'Raw Data'!$K$2:$K$1054,7) -> 40.38447
A37: 2016-08 | B37: =SUMIFS('Raw Data'!$B$2:$B$1054,'Raw Data'!$J$2:$J$1054,2016,'Raw Data'!$K$2:$K$1054,8) -> 4343329.4 | C37: =SUMIFS('Raw Data'!$D$2:$D$1054,'Raw Data'!$J$2:$J$1054,2016,'Raw Data'!$K$2:$K$1054,8) -> 123621 | D37: =SUMIFS('Raw Data'!$G$2:$G$1054,'Raw Data'!$J$2:$J$1054,2016,'Raw Data'!$K$2:$K$1054,8) -> -136458.24 | E37: =D37/B37 -> -0.031417889 | F37: =AVERAGEIFS('Raw Data'!$E$2:$E$1054,'Raw Data'!$J$2:$J$1054,2016,'Raw Data'!$K$2:$K$1054,8) -> 36.878844
A38: 2016-09 | B38: =SUMIFS('Raw Data'!$B$2:$B$1054,'Raw Data'!$J$2:$J$1054,2016,'Raw Data'!$K$2:$K$1054,9) -> 3259542.5 | C38: =SUMIFS('Raw Data'!$D$2:$D$1054,'Raw Data'!$J$2:$J$1054,2016,'Raw Data'!$K$2:$K$1054,9) -> 88672 | D38: =SUMIFS('Raw Data'!$G$2:$G$1054,'Raw Data'!$J$2:$J$1054,2016,'Raw Data'!$K$2:$K$1054,9) -> 49345.214 | E38: =D38/B38 -> 0.015138693 | F38: =AVERAGEIFS('Raw Data'!$E$2:$E$1054,'Raw Data'!$J$2:$J$1054,2016,'Raw Data'!$K$2:$K$1054,9) -> 38.892587
A39: 2016-10 | B39: =SUMIFS('Raw Data'!$B$2:$B$1054,'Raw Data'!$J$2:$J$1054,2016,'Raw Data'!$K$2:$K$1054,10) -> 2329172.7 | C39: =SUMIFS('Raw Data'!$D$2:$D$1054,'Raw Data'!$J$2:$J$1054,2016,'Raw Data'!$K$2:$K$1054,10) -> 56667 | D39: =SUMIFS('Raw Data'!$G$2:$G$1054,'Raw Data'!$J$2:$J$1054,2016,'Raw Data'!$K$2:$K$1054,10) -> 219961.64 | E39: =D39/B39 -> 0.094437671 | F39: =AVERAGEIFS('Raw Data'!$E$2:$E$1054,'Raw Data'!$J$2:$J$1054,2016,'Raw Data'!$K$2:$K$1054,10) -> 41.627311
A40: 2016-11 | B40: =SUMIFS('Raw Data'!$B$2:$B$1054,'Raw Data'!$J$2:$J$1054,2016,'Raw Data'!$K$2:$K$1054,11) -> 1851029.9 | C40: =SUMIFS('Raw Data'!$D$2:$D$1054,'Raw Data'!$J$2:$J$1054,2016,'Raw Data'!$K$2:$K$1054,11) -> 43107 | D40: =SUMIFS('Raw Data'!$G$2:$G$1054,'Raw Data'!$J$2:$J$1054,2016,'Raw Data'!$K$2:$K$1054,11) -> 126556.98 | E40: =D40/B40 -> 0.06837112 | F40: =AVERAGEIFS('Raw Data'!$E$2:$E$1054,'Raw Data'!$J$2:$J$1054,2016,'Raw Data'!$K$2:$K$1054,11) -> 42.978499

Sheet Pivot - Yearly
A1: Yearly Sales Pivot
A2: Note: 2013 and 2016 are partial years (2 days and 11 months of data respectively)
A4: Year | B4: Total Sales (R) | C4: Total Quantity | D4: Total Gross Profit (R) | E4: Gross Profit % | F4: Avg Price per Unit (R)
A5: 2013 | B5: =SUMIFS('Raw Data'!$B$2:$B$1054,'Raw Data'!$J$2:$J$1054,2013) -> 524283.45 | C5: =SUMIFS('Raw Data'!$D$2:$D$1054,'Raw Data'!$J$2:$J$1054,2013) -> 16095 | D5: =SUMIFS('Raw Data'!$G$2:$G$1054,'Raw Data'!$J$2:$J$1054,2013) -> -12782.289 | E5: =D5/B5 -> -0.024380493 | F5: =AVERAGEIFS('Raw Data'!$E$2:$E$1054,'Raw Data'!$J$2:$J$1054,2013) -> 32.604266
A6: 2014 | B6: =SUMIFS('Raw Data'!$B$2:$B$1054,'Raw Data'!$J$2:$J$1054,2014) -> 75414976 | C6: =SUMIFS('Raw Data'!$D$2:$D$1054,'Raw Data'!$J$2:$J$1054,2014) -> 2254230 | D6: =SUMIFS('Raw Data'!$G$2:$G$1054,'Raw Data'!$J$2:$J$1054,2014) -> -2265874 | E6: =D6/B6 -> -0.030045412 | F6: =AVERAGEIFS('Raw Data'!$E$2:$E$1054,'Raw Data'!$J$2:$J$1054,2014) -> 34.573533
A7: 2015 | B7: =SUMIFS('Raw Data'!$B$2:$B$1054,'Raw Data'!$J$2:$J$1054,2015) -> 64017593 | C7: =SUMIFS('Raw Data'!$D$2:$D$1054,'Raw Data'!$J$2:$J$1054,2015) -> 1715089 | D7: =SUMIFS('Raw Data'!$G$2:$G$1054,'Raw Data'!$J$2:$J$1054,2015) -> -3899610.4 | E7: =D7/B7 -> -0.060914668 | F7: =AVERAGEIFS('Raw Data'!$E$2:$E$1054,'Raw Data'!$J$2:$J$1054,2015) -> 38.327482
A8: 2016 | B8: =SUMIFS('Raw Data'!$B$2:$B$1054,'Raw Data'!$J$2:$J$1054,2016) -> 46952976 | C8: =SUMIFS('Raw Data'!$D$2:$D$1054,'Raw Data'!$J$2:$J$1054,2016) -> 1294458 | D8: =SUMIFS('Raw Data'!$G$2:$G$1054,'Raw Data'!$J$2:$J$1054,2016) -> -938014.46 | E8: =D8/B8 -> -0.019977743 | F8: =AVERAGEIFS('Raw Data'!$E$2:$E$1054,'Raw Data'!$J$2:$J$1054,2016) -> 38.515993

Sheet Pivot - Day of Week
A1: Day-of-Week Pivot
A2: Built with AVERAGEIFS against Raw Data day_of_week column
A4: Day of Week | B4: Avg Daily Sales (R) | C4: Avg Daily Quantity | D4: Avg Price per Unit (R) | E4: Avg Gross Profit %
A5: Monday | B5: =AVERAGEIFS('Raw Data'!$B$2:$B$1054,'Raw Data'!$M$2:$M$1054,"Monday") -> 156313.03 | C5: =AVERAGEIFS('Raw Data'!$D$2:$D$1054,'Raw Data'!$M$2:$M$1054,"Monday") -> 4400.0464 | D5: =AVERAGEIFS('Raw Data'!$E$2:$E$1054,'Raw Data'!$M$2:$M$1054,"Monday") -> 37.242813 | E5: =AVERAGEIFS('Raw Data'!$H$2:$H$1054,'Raw Data'!$M$2:$M$1054,"Monday") -> -0.0042137865
A6: Tuesday | B6: =AVERAGEIFS('Raw Data'!$B$2:$B$1054,'Raw Data'!$M$2:$M$1054,"Tuesday") -> 137314.86 | C6: =AVERAGEIFS('Raw Data'!$D$2:$D$1054,'Raw Data'!$M$2:$M$1054,"Tuesday") -> 3851.702 | D6: =AVERAGEIFS('Raw Data'!$E$2:$E$1054,'Raw Data'!$M$2:$M$1054,"Tuesday") -> 37.232696 | E6: =AVERAGEIFS('Raw Data'!$H$2:$H$1054,'Raw Data'!$M$2:$M$1054,"Tuesday") -> -0.0041855288
A7: Wednesday | B7: =AVERAGEIFS('Raw Data'!$B$2:$B$1054,'Raw Data'!$M$2:$M$1054,"Wednesday") -> 145890.66 | C7: =AVERAGEIFS('Raw Data'!$D$2:$D$1054,'Raw Data'!$M$2:$M$1054,"Wednesday") -> 4105.9934 | D7: =AVERAGEIFS('Raw Data'!$E$2:$E$1054,'Raw Data'!$M$2:$M$1054,"Wednesday") -> 37.015791 | E7: =AVERAGEIFS('Raw Data'!$H$2:$H$1054,'Raw Data'!$M$2:$M$1054,"Wednesday") -> -0.0096822122
A8: Thursday | B8: =AVERAGEIFS('Raw Data'!$B$2:$B$1054,'Raw Data'!$M$2:$M$1054,"Thursday") -> 141084.76 | C8: =AVERAGEIFS('Raw Data'!$D$2:$D$1054,'Raw Data'!$M$2:$M$1054,"Thursday") -> 3969.22 | D8: =AVERAGEIFS('Raw Data'!$E$2:$E$1054,'Raw Data'!$M$2:$M$1054,"Thursday") -> 37.161422 | E8: =AVERAGEIFS('Raw Data'!$H$2:$H$1054,'Raw Data'!$M$2:$M$1054,"Thursday") -> -0.0055248025
A9: Friday | B9: =AVERAGEIFS('Raw Data'!$B$2:$B$1054,'Raw Data'!$M$2:$M$1054,"Friday") -> 245313.97 | C9: =AVERAGEIFS('Raw Data'!$D$2:$D$1054,'Raw Data'!$M$2:$M$1054,"Friday") -> 6955.3933 | D9: =AVERAGEIFS('Raw Data'!$E$2:$E$1054,'Raw Data'!$M$2:$M$1054,"Friday") -> 36.982263 | E9: =AVERAGEIFS('Raw Data'!$H$2:$H$1054,'Raw Data'!$M$2:$M$1054,"Friday") -> -0.011043695
A10: Saturday | B10: =AVERAGEIFS('Raw Data'!$B$2:$B$1054,'Raw Data'!$M$2:$M$1054,"Saturday") -> 279047.26 | C10: =AVERAGEIFS('Raw Data'!$D$2:$D$1054,'Raw Data'!$M$2:$M$1054,"Saturday") -> 7937.3067 | D10: =AVERAGEIFS('Raw Data'!$E$2:$E$1054,'Raw Data'!$M$2:$M$1054,"Saturday") -> 36.857654 | E10: =AVERAGEIFS('Raw Data'!$H$2:$H$1054,'Raw Data'!$M$2:$M$1054,"Saturday") -> -0.015141209
A11: Sunday | B11: =AVERAGEIFS('Raw Data'!$B$2:$B$1054,'Raw Data'!$M$2:$M$1054,"Sunday") -> 138170.86 | C11: =AVERAGEIFS('Raw Data'!$D$2:$D$1054,'Raw Data'!$M$2:$M$1054,"Sunday") -> 3897.1 | D11: =AVERAGEIFS('Raw Data'!$E$2:$E$1054,'Raw Data'!$M$2:$M$1054,"Sunday") -> 37.015503 | E11: =AVERAGEIFS('Raw Data'!$H$2:$H$1054,'Raw Data'!$M$2:$M$1054,"Sunday") -> -0.011511583

Sheet Pivot - Promo vs Non-Promo
A1: Promotional vs Non-Promotional Days
A2: promo_candidate flag: days with a notable price drop + quantity spike vs the trailing rolling average
A4: Segment | B4: # Days | C4: Avg Price per Unit (R) | D4: Avg Daily Quantity | E4: Avg Gross Profit %
A5: Non-Promotional | B5: =COUNTIFS('Raw Data'!$S$2:$S$1054,FALSE()) -> 925 | C5: =AVERAGEIFS('Raw Data'!$E$2:$E$1054,'Raw Data'!$S$2:$S$1054,FALSE()) -> 37.344364 | D5: =AVERAGEIFS('Raw Data'!$D$2:$D$1054,'Raw Data'!$S$2:$S$1054,FALSE()) -> 4634.9665 | E5: =AVERAGEIFS('Raw Data'!$H$2:$H$1054,'Raw Data'!$S$2:$S$1054,FALSE()) -> 0.00044409709
A6: Promotional | B6: =COUNTIFS('Raw Data'!$S$2:$S$1054,TRUE()) -> 128 | C6: =AVERAGEIFS('Raw Data'!$E$2:$E$1054,'Raw Data'!$S$2:$S$1054,TRUE()) -> 35.11075 | D6: =AVERAGEIFS('Raw Data'!$D$2:$D$1054,'Raw Data'!$S$2:$S$1054,TRUE()) -> 7754.125 | E6: =AVERAGEIFS('Raw Data'!$H$2:$H$1054,'Raw Data'!$S$2:$S$1054,TRUE()) -> -0.075189797

Sheet Promo Elasticity
A1: Metric 5 — Price Elasticity of Demand During Promotions
A2: Three promotional periods (longest contiguous "promo_candidate" runs) analysed against a 30-day pre-promotion, non-promotional baseline. PED = %Δ Quantity / %Δ Price.
A4: Period | B4: Promo Start | C4: Promo End | D4: Baseline Window (30 days pre-promo, excl. promo days) | E4: Baseline Avg Price (R) | F4: Promo Avg Price (R) | G4: % Δ Price | H4: Baseline Avg Qty | I4: Promo Avg Qty | J4: % Δ Qty | K4: Price Elasticity of Demand | L4: Baseline GP % | M4: Promo GP %
A5: Period 1 | B5: 42514 | C5: 42524 | D5: =TEXT(O5,"yyyy-mm-dd")&" to day before promo start" -> 2016-04-24 to day before promo start | E5: =AVERAGEIFS('Raw Data'!$E$2:$E$1054,'Raw Data'!$A$2:$A$1054,">="&$O5,'Raw Data'!$A$2:$A$1054,"<"&$B5,'Raw Data'!$S$2:$S$1054,FALSE()) -> 38.111765 | F5: =AVERAGEIFS('Raw Data'!$E$2:$E$1054,'Raw Data'!$A$2:$A$1054,">="&$B5,'Raw Data'!$A$2:$A$1054,"<="&$C5) -> 34.352331 | G5: =(F5-E5)/E5 -> -0.098642346 | H5: =AVERAGEIFS('Raw Data'!$D$2:$D$1054,'Raw Data'!$A$2:$A$1054,">="&$O5,'Raw Data'!$A$2:$A$1054,"<"&$B5,'Raw Data'!$S$2:$S$1054,FALSE()) -> 5203.8667 | I5: =AVERAGEIFS('Raw Data'!$D$2:$D$1054,'Raw Data'!$A$2:$A$1054,">="&$B5,'Raw Data'!$A$2:$A$1054,"<="&$C5) -> 7935.8182 | J5: =(I5-H5)/H5 -> 0.52498492 | K5: =J5/G5 -> -5.3221049 | L5: =AVERAGEIFS('Raw Data'!$H$2:$H$1054,'Raw Data'!$A$2:$A$1054,">="&$O5,'Raw Data'!$A$2:$A$1054,"<"&$B5,'Raw Data'!$S$2:$S$1054,FALSE()) -> 0.028935827 | M5: =AVERAGEIFS('Raw Data'!$H$2:$H$1054,'Raw Data'!$A$2:$A$1054,">="&$B5,'Raw Data'!$A$2:$A$1054,"<="&$C5) -> -0.059367305 | O5: 42484
A6: Period 2 | B6: 42270 | C6: 42279 | D6: =TEXT(O6,"yyyy-mm-dd")&" to day before promo start" -> 2015-08-24 to day before promo start | E6: =AVERAGEIFS('Raw Data'!$E$2:$E$1054,'Raw Data'!$A$2:$A$1054,">="&$O6,'Raw Data'!$A$2:$A$1054,"<"&$B6,'Raw Data'!$S$2:$S$1054,FALSE()) -> 37.948221 | F6: =AVERAGEIFS('Raw Data'!$E$2:$E$1054,'Raw Data'!$A$2:$A$1054,">="&$B6,'Raw Data'!$A$2:$A$1054,"<="&$C6) -> 33.404647 | G6: =(F6-E6)/E6 -> -0.11973089 | H6: =AVERAGEIFS('Raw Data'!$D$2:$D$1054,'Raw Data'!$A$2:$A$1054,">="&$O6,'Raw Data'!$A$2:$A$1054,"<"&$B6,'Raw Data'!$S$2:$S$1054,FALSE()) -> 2887.381 | I6: =AVERAGEIFS('Raw Data'!$D$2:$D$1054,'Raw Data'!$A$2:$A$1054,">="&$B6,'Raw Data'!$A$2:$A$1054,"<="&$C6) -> 7819.4 | J6: =(I6-H6)/H6 -> 1.708129 | K6: =J6/G6 -> -14.266402 | L6: =AVERAGEIFS('Raw Data'!$H$2:$H$1054,'Raw Data'!$A$2:$A$1054,">="&$O6,'Raw Data'!$A$2:$A$1054,"<"&$B6,'Raw Data'!$S$2:$S$1054,FALSE()) -> 0.020200961 | M6: =AVERAGEIFS('Raw Data'!$H$2:$H$1054,'Raw Data'!$A$2:$A$1054,">="&$B6,'Raw Data'!$A$2:$A$1054,"<="&$C6) -> -0.13083613 | O6: 42240
A7: Period 3 | B7: 42391 | C7: 42399 | D7: =TEXT(O7,"yyyy-mm-dd")&" to day before promo start" -> 2015-12-23 to day before promo start | E7: =AVERAGEIFS('Raw Data'!$E$2:$E$1054,'Raw Data'!$A$2:$A$1054,">="&$O7,'Raw Data'!$A$2:$A$1054,"<"&$B7,'Raw Data'!$S$2:$S$1054,FALSE()) -> 40.156123 | F7: =AVERAGEIFS('Raw Data'!$E$2:$E$1054,'Raw Data'!$A$2:$A$1054,">="&$B7,'Raw Data'!$A$2:$A$1054,"<="&$C7) -> 34.056916 | G7: =(F7-E7)/E7 -> -0.15188735 | H7: =AVERAGEIFS('Raw Data'!$D$2:$D$1054,'Raw Data'!$A$2:$A$1054,">="&$O7,'Raw Data'!$A$2:$A$1054,"<"&$B7,'Raw Data'!$S$2:$S$1054,FALSE()) -> 3268.96 | I7: =AVERAGEIFS('Raw Data'!$D$2:$D$1054,'Raw Data'!$A$2:$A$1054,">="&$B7,'Raw Data'!$A$2:$A$1054,"<="&$C7) -> 8096.6667 | J7: =(I7-H7)/H7 -> 1.4768326 | K7: =J7/G7 -> -9.7232099 | L7: =AVERAGEIFS('Raw Data'!$H$2:$H$1054,'Raw Data'!$A$2:$A$1054,">="&$O7,'Raw Data'!$A$2:$A$1054,"<"&$B7,'Raw Data'!$S$2:$S$1054,FALSE()) -> 0.04614042 | M7: =AVERAGEIFS('Raw Data'!$H$2:$H$1054,'Raw Data'!$A$2:$A$1054,">="&$B7,'Raw Data'!$A$2:$A$1054,"<="&$C7) -> -0.091084654 | O7: 42361
A10: Interpretation
A11: All three periods show highly elastic demand (|PED| well above 1): a ~10–15% price cut during promotion drives a 50–170% jump in average daily quantity sold. However, promotional gross profit % turns negative in every period (baseline was positive, +2% to +5%), while promo-period margin falls to roughly -6% to -13%. In other words, the discount depth is currently cutting deeper than the volume uplift can compensate for — the product sells far better by units at a promotional price, but the store loses money doing it under this pricing structure. A shallower discount (e.g. 5-8% instead of 10-15%) would likely still trigger a large volume response given how elastic demand is, while keeping gross margin closer to breakeven or positive.
